<?xml version="1.0"?>
<robot name="barista_robot" xmlns:xacro="http://ros.org/wiki/xacro">
<!-- Created with Liquid Technologies Online Tools 1.0 (https://www.liquid-technologies.com) -->

<!-- Include macro -->
<xacro:include filename="$(find barista_robot_description)/xacro/wheel.xacro" />
<xacro:include filename="$(find barista_robot_description)/xacro/standoff.xacro" />
<xacro:include filename="$(find barista_robot_description)/xacro/cup_holder_tray.xacro" />

<!-- Define the argument for including the laser -->
<xacro:arg name="include_laser" default="true" />

<!-- Lidar Sensor Macro Definition -->
<xacro:macro name="laser_scanner">
    <!-- Lidar Sensor -->
    <link name="lidar">
        <visual>
            <origin rpy="0 0 0" xyz="0.0 0 -0.05" />
            <geometry>
                <mesh filename="package://barista_robot_description/meshes/hokuyo_urg_04lx.dae"/>
            </geometry>
        </visual>
    </link>
    <joint name="lidar_joint" type="fixed">
        <origin rpy="0 0 0" xyz="-0.05 0 0.125" />
        <parent link="base_link" />
        <child link="lidar" />
    </joint>
    <gazebo reference="lidar">
        <material>Gazebo/Black</material>
    </gazebo>
    <!-- Lidar plugin -->
    <gazebo reference="lidar">
        <sensor name="sensor_ray" type="ray">
            <pose>0 0 0 0 0 0</pose>
            <ray>
                <scan>
                    <horizontal>
                        <samples>200</samples>
                        <resolution>1.0</resolution>
                        <min_angle>-3.14</min_angle>
                        <max_angle>3.14</max_angle>
                    </horizontal>
                </scan>
                <range>
                    <min>0.025</min>
                    <max>5.0</max>
                </range>
            </ray>
            <always_on>true</always_on>
            <visualize>true</visualize>
            <update_rate>100.0</update_rate>
            <plugin name="laser" filename="libgazebo_ros_ray_sensor.so">
                <ros>
                    <remapping>~/out:=scan</remapping>
                </ros>
                <output_type>sensor_msgs/LaserScan</output_type>
            </plugin>
        </sensor>
    </gazebo>
</xacro:macro>

<!-- Conditional inclusion of the laser scanner -->
<xacro:if value="$(arg include_laser)">
    <xacro:laser_scanner />
</xacro:if>

  <material name="blue">
    <color rgba="0.0 0.0 1.0 1" />
  </material>

  <material name="black">
    <color rgba="0.0 0.0 0.0 1" />
  </material>

  <material name="white">
    <color rgba="1.0 1.0 1.0 1" />
  </material>

  <material name="blue_box">
    <color rgba="0.088656 0.428691 0.491021 1" />
  </material>

  <link name="base_link">
  </link>

  <!-- Body -->

  <link name="chassis">
    <visual>
      <geometry>
        <cylinder length="0.155" radius="0.178" />
      </geometry>
      <material name="blue" />
    </visual>
    <collision>
      <geometry>
        <cylinder length="0.155" radius="0.178" />
      </geometry>
    </collision>
    <inertial>
      <origin xyz="0 0 0" rpy="0 0 0" />
      <mass value="0.42857142857142855" />
      <inertia ixx="0.00425275" ixy="0.0" ixz="0.0" iyy="0.00425275" iyz="0.0" izz="0.00678942857142857" />
    </inertial>
  </link>

  <joint name="base_link_joint" type="fixed">
    <origin rpy="0 0 0" xyz="0 0 0" />
    <parent link="base_link" />
    <child link="chassis" />
  </joint>

  <gazebo reference="chassis">
        <material>Gazebo/Blue</material>
  </gazebo>

  <!-- Front standoffs -->
  <xacro:standoff name="front_right_standoff" />

  <joint name="front_right_standoff_joint" type="fixed">
    <origin rpy="0 0 0" xyz="0.025 -0.15 0.1875" />
    <parent link="base_link" />
    <child link="front_right_standoff" />
  </joint>

  <xacro:standoff name="front_left_standoff" />

  <joint name="front_left_standoff_joint" type="fixed">
    <origin rpy="0 0 0" xyz="0.025 0.15 0.1875" />
    <parent link="base_link" />
    <child link="front_left_standoff" />
  </joint>

  <!-- Back standoffs -->

  <xacro:standoff name="back_right_standoff" />

  <joint name="back_right_standoff_joint" type="fixed">
    <origin rpy="0 0 0" xyz="-0.025 -0.15 0.1875" />
    <parent link="base_link" />
    <child link="back_right_standoff" />
  </joint>

  <xacro:standoff name="back_left_standoff" />

  <joint name="back_left_standoff_joint" type="fixed">
    <origin rpy="0 0 0" xyz="-0.025 0.15 0.1875" />
    <parent link="base_link" />
    <child link="back_left_standoff" />
  </joint>

  <!-- Cup holder tray -->

  <xacro:cup_holder_tray name="cup_holder" />

  <joint name="cup_holder_joint" type="fixed">
    <origin rpy="0 0 0" xyz="0.0 0.0 0.3425" />
    <parent link="base_link" />
    <child link="cup_holder" />
  </joint>

  <gazebo reference="cup_holder">
        <material>Gazebo/Blue</material>
  </gazebo>

  <!-- Wheel Left -->

  <xacro:wheel prefix="left" />

  <gazebo reference="left_wheel">
    <kp>1000000000000000000000000000.0</kp>
    <kd>1000000000000000000000000000.0</kd>
    <mu1>10.0</mu1>
    <mu2>10.0</mu2>
    <material>Gazebo/Black</material>
  </gazebo>

  <joint name="joint_left_wheel" type="continuous">
    <origin rpy="0 0 0" xyz="0 0.12 -0.0775" />
    <child link="left_wheel" />
    <parent link="chassis" />
    <axis rpy="0 0 0" xyz="0 1 0" />
    <limit effort="10000" velocity="1000" />
    <joint_properties damping="1.0" friction="1.0" />
  </joint>

  <!-- Wheel Right -->

  <xacro:wheel prefix="right" />

  <gazebo reference="right_wheel">
    <kp>1000000000000000000000000000.0</kp>
    <kd>1000000000000000000000000000.0</kd>
    <mu1>10.0</mu1>
    <mu2>10.0</mu2>
    <material>Gazebo/Black</material>
  </gazebo>

  <joint name="joint_right_wheel" type="continuous">
    <origin rpy="0 0 0" xyz="0 -0.12 -0.0775" />
    <child link="right_wheel" />
    <parent link="chassis" />
    <axis rpy="0 0 0" xyz="0 1 0" />
    <limit effort="10000" velocity="1000" />
    <joint_properties damping="1.0" friction="1.0" />
  </joint>

  <!-- Caster Wheel Front -->

  <link name="front_yaw_link">
    <visual>
      <origin rpy="0 1.5707 1.5707" xyz="0 0 0" />
      <geometry>
        <cylinder length="0.001" radius="0.0045000000000000005"/>
      </geometry>
      <material name="blue" />
    </visual>

    <collision>
      <origin rpy="0 1.5707 1.5707" xyz="0 0 0" />
      <geometry>
        <cylinder length="0.001" radius="0.0045000000000000005"/>
      </geometry>
    </collision>

    <inertial>
          <origin rpy="0 1.5707 1.5707" xyz="0 0 0"/>
          <mass value="0.001"/>
          <inertia ixx="5.145833333333334e-09" ixy="0" ixz="0" iyy="5.145833333333334e-09" iyz="0" izz="1.0125000000000003e-08"/>
    </inertial>
  </link>

  <gazebo reference="front_yaw_link">
        <material>Gazebo/Blue</material>
  </gazebo>

  <joint name="front_yaw_joint" type="continuous">
    <origin rpy="0 0 0" xyz="0.12 0 -0.1082" />
    <parent link="chassis" />
    <child link="front_yaw_link" />
    <axis xyz="0 0 1" />
    <limit effort="1000.0" velocity="100.0" />
    <dynamics damping="0.0" friction="0.1" />
  </joint>
  
  <link name="front_roll_link">
     <visual>
      <origin rpy="0 1.5707 1.5707" xyz="0 0 0" />
      <geometry>
        <cylinder length="0.001" radius="0.0045000000000000005"/>
      </geometry>
      <material name="blue" />
    </visual>

    <collision>
      <origin rpy="0 1.5707 1.5707" xyz="0 0 0" />
      <geometry>
        <cylinder length="0.001" radius="0.0045000000000000005"/>
      </geometry>
    </collision>

    <inertial>
          <origin rpy="0 1.5707 1.5707" xyz="0 0 0"/>
          <mass value="0.001"/>
          <inertia ixx="5.145833333333334e-09" ixy="0" ixz="0" iyy="5.145833333333334e-09" iyz="0" izz="1.0125000000000003e-08"/>
    </inertial>
  </link>

  <gazebo reference="front_roll_link">
        <material>Gazebo/Red</material>
  </gazebo>

  <joint name="front_roll_joint" type="continuous">
    <origin rpy="0 0 0" xyz="0 0 0" />
    <parent link="front_yaw_link" />
    <child link="front_roll_link" />
    <axis xyz="1 0 0" />
    <limit effort="1000.0" velocity="100.0" />
    <dynamics damping="0.0" friction="0.1" />
  </joint>

  <link name="front_pitch_link">
     <visual>
      <origin rpy="0 1.5707 1.5707" xyz="0 0 0" />
      <geometry>
        <cylinder length="0.001" radius="0.0045000000000000005"/>
      </geometry>
      <material name="blue" />
    </visual>

    <collision>
      <origin rpy="0 1.5707 1.5707" xyz="0 0 0" />
      <geometry>
        <cylinder length="0.001" radius="0.0045000000000000005"/>
      </geometry>
    </collision>

    <inertial>
          <origin rpy="0 1.5707 1.5707" xyz="0 0 0"/>
          <mass value="0.001"/>
          <inertia ixx="5.145833333333334e-09" ixy="0" ixz="0" iyy="5.145833333333334e-09" iyz="0" izz="1.0125000000000003e-08"/>
    </inertial>
  </link>

  <gazebo reference="front_pitch_link">
    <kp>1000000000000000000000000000.0</kp>
    <kd>1000000000000000000000000000.0</kd>
    <mu1>0.5</mu1>
    <mu2>0.5</mu2>
    <material>Gazebo/Purple</material>
  </gazebo>

  <joint name="front_pitch_joint" type="continuous">
    <origin rpy="0 0 0" xyz="0 0 0" />
    <parent link="front_roll_link" />
    <child link="front_pitch_link" />
    <axis xyz="0 1 0" />
    <limit effort="1000.0" velocity="100.0" />
    <dynamics damping="0.0" friction="0.1" />
  </joint>

  <!-- Caster Wheel Back -->

  <link name="back_yaw_link">
     <visual>
      <origin rpy="0 1.5707 1.5707" xyz="0 0 0" />
      <geometry>
        <cylinder length="0.001" radius="0.0045000000000000005"/>
      </geometry>
      <material name="blue" />
    </visual>

    <collision>
      <origin rpy="0 1.5707 1.5707" xyz="0 0 0" />
      <geometry>
        <cylinder length="0.001" radius="0.0045000000000000005"/>
      </geometry>
    </collision>

    <inertial>
          <origin rpy="0 1.5707 1.5707" xyz="0 0 0"/>
          <mass value="0.001"/>
          <inertia ixx="5.145833333333334e-09" ixy="0" ixz="0" iyy="5.145833333333334e-09" iyz="0" izz="1.0125000000000003e-08"/>
    </inertial>
  </link>

  <gazebo reference="back_yaw_link">
        <material>Gazebo/Blue</material>
  </gazebo>

  <joint name="back_yaw_joint" type="continuous">
    <origin rpy="0 0 0" xyz="-0.12 0 -0.1082" />
    <parent link="chassis" />
    <child link="back_yaw_link" />
    <axis xyz="0 0 1" />
    <limit effort="1000.0" velocity="100.0" />
    <dynamics damping="0.0" friction="0.1" />
  </joint>

  <link name="back_roll_link">
     <visual>
      <origin rpy="0 1.5707 1.5707" xyz="0 0 0" />
      <geometry>
        <cylinder length="0.001" radius="0.0045000000000000005"/>
      </geometry>
      <material name="blue" />
    </visual>

    <collision>
      <origin rpy="0 1.5707 1.5707" xyz="0 0 0" />
      <geometry>
        <cylinder length="0.001" radius="0.0045000000000000005"/>
      </geometry>
    </collision>

    <inertial>
          <origin rpy="0 1.5707 1.5707" xyz="0 0 0"/>
          <mass value="0.001"/>
          <inertia ixx="5.145833333333334e-09" ixy="0" ixz="0" iyy="5.145833333333334e-09" iyz="0" izz="1.0125000000000003e-08"/>
    </inertial>
  </link>

  <gazebo reference="back_roll_link">
        <material>Gazebo/Red</material>
  </gazebo>

  <joint name="back_roll_joint" type="continuous">
    <origin rpy="0 0 0" xyz="0 0 0" />
    <parent link="back_yaw_link" />
    <child link="back_roll_link" />
    <axis xyz="1 0 0" />
    <limit effort="1000.0" velocity="100.0" />
    <dynamics damping="0.0" friction="0.1" />
  </joint>

  <link name="back_pitch_link">
     <visual>
      <origin rpy="0 1.5707 1.5707" xyz="0 0 0" />
      <geometry>
        <cylinder length="0.001" radius="0.0045000000000000005"/>
      </geometry>
      <material name="blue" />
    </visual>

    <collision>
      <origin rpy="0 1.5707 1.5707" xyz="0 0 0"/>
      <geometry>
        <cylinder length="0.001" radius="0.0045000000000000005"/>
      </geometry>
    </collision>

    <inertial>
          <origin rpy="0 1.5707 1.5707" xyz="0 0 0"/>
          <mass value="0.001"/>
          <inertia ixx="5.145833333333334e-09" ixy="0" ixz="0" iyy="5.145833333333334e-09" iyz="0" izz="1.0125000000000003e-08"/>
    </inertial>
  </link>

  <gazebo reference="back_pitch_link">
    <kp>1000000000000000000000000000.0</kp>
    <kd>1000000000000000000000000000.0</kd>
    <mu1>0.5</mu1>
    <mu2>0.5</mu2>
    <material>Gazebo/Yellow</material>
  </gazebo>

  <joint name="back_pitch_joint" type="continuous">
    <origin rpy="0 0 0" xyz="0 0 0" />
    <parent link="back_roll_link" />
    <child link="back_pitch_link" />
    <axis xyz="0 1 0" />
    <limit effort="1000.0" velocity="100.0" />
    <dynamics damping="0.0" friction="0.1" />
  </joint>

  <!-- PLUGINS -->

  <!-- JOINT PUBLISHER -->
  <gazebo>
    <plugin name="barista_robot_joint_state" filename="libgazebo_ros_joint_state_publisher.so">
      <ros>
          <remapping>~/out:=joint_states</remapping>
      </ros>
      <update_rate>30</update_rate>

      <joint_name>joint_left_wheel</joint_name>
      <joint_name>joint_right_wheel</joint_name>
      <joint_name>front_yaw_joint</joint_name>
      <joint_name>back_yaw_joint</joint_name>
      <joint_name>front_roll_joint</joint_name>
      <joint_name>back_roll_joint</joint_name>
      <joint_name>front_pitch_joint</joint_name>
      <joint_name>back_pitch_joint</joint_name>
      
    </plugin>
  </gazebo>

  <!-- Differential drive -->
  <gazebo>
    <plugin filename="libgazebo_ros_diff_drive.so" name="differential_drive_controller">

      <!-- wheels -->
      <left_joint>joint_left_wheel</left_joint>
      <right_joint>joint_right_wheel</right_joint>

      <!-- kinematics -->
      <wheel_separation>0.24</wheel_separation>
      <wheel_diameter>0.0704</wheel_diameter>

      <!-- limits -->
      <max_wheel_torque>0.5</max_wheel_torque>
      <max_wheel_acceleration>2.0</max_wheel_acceleration>

      <!-- output -->
      <publish_odom>true</publish_odom>
      <publish_odom_tf>true</publish_odom_tf>

      <odometry_frame>odom</odometry_frame>
      <robot_base_frame>base_link</robot_base_frame>

    </plugin>
  </gazebo>

</robot>